Traceback (most recent call last):
  File "C:\Users\migue\miniconda3\envs\ml_venv\lib\site-packages\jupyter_core\utils\__init__.py", line 154, in wrapped
    asyncio.get_running_loop()
RuntimeError: no running event loop

During handling of the above exception, another exception occurred:

Traceback (most recent call last):
  File "C:\Users\migue\miniconda3\envs\ml_venv\lib\site-packages\jupyter_cache\executors\utils.py", line 58, in single_nb_execution
    executenb(
  File "C:\Users\migue\miniconda3\envs\ml_venv\lib\site-packages\nbclient\client.py", line 1319, in execute
    return NotebookClient(nb=nb, resources=resources, km=km, **kwargs).execute()
  File "C:\Users\migue\miniconda3\envs\ml_venv\lib\site-packages\jupyter_core\utils\__init__.py", line 158, in wrapped
    return loop.run_until_complete(inner)
  File "C:\Users\migue\miniconda3\envs\ml_venv\lib\asyncio\base_events.py", line 647, in run_until_complete
    return future.result()
  File "C:\Users\migue\miniconda3\envs\ml_venv\lib\site-packages\nbclient\client.py", line 709, in async_execute
    await self.async_execute_cell(
  File "C:\Users\migue\miniconda3\envs\ml_venv\lib\site-packages\nbclient\client.py", line 1062, in async_execute_cell
    await self._check_raise_for_error(cell, cell_index, exec_reply)
  File "C:\Users\migue\miniconda3\envs\ml_venv\lib\site-packages\nbclient\client.py", line 918, in _check_raise_for_error
    raise CellExecutionError.from_cell_and_msg(cell, exec_reply_content)
nbclient.exceptions.CellExecutionError: An error occurred while executing the following cell:
------------------
y_pred_log = LogMod.predic(X_test)
print(confusion_matrix(y_test, y_pred_log))
print(classification_report(y_test, y_pred_log))
------------------


[1;31m---------------------------------------------------------------------------[0m
[1;31mAttributeError[0m                            Traceback (most recent call last)
Cell [1;32mIn[32], line 1[0m
[1;32m----> 1[0m y_pred_log [38;5;241m=[39m [43mLogMod[49m[38;5;241;43m.[39;49m[43mpredic[49m(X_test)
[0;32m      2[0m [38;5;28mprint[39m(confusion_matrix(y_test, y_pred_log))
[0;32m      3[0m [38;5;28mprint[39m(classification_report(y_test, y_pred_log))

[1;31mAttributeError[0m: 'LogisticRegression' object has no attribute 'predic'

